<!--
목적   : 차량 모델 설계 (open truck)
작성자 : 김준호
최초 작성일자 : 2025‑05‑23
수정자 : 김준호
최종 수정일자 : 2025‑05‑25
-->
<mujoco model="open truck">
  <!-- 컴파일러 : 관성 자동 적용 -->
  <compiler inertiafromgeom="true"/>

  <!-- 옵션 : 시뮬레이션 시간 주기, 중력, 적분기 -->
  <option timestep="{TIMESTEP}" gravity="0 0 {GRAVITY_Z}" integrator="{INTEGRATOR}"/>

  <!-- ========= 에셋 ========= -->
  <asset>
    <texture name="grid" type="2d" builtin="checker"
            rgb1=".2 .3 .4" rgb2=".8 .8 .8" width="512" height="512"/>
    <material name="grid_mat" texture="grid" texrepeat="5 5"
            specular=".3" shininess=".3"/>
    <texture name="wheel_pat" type="2d" builtin="checker"
            rgb1="1 1 1" rgb2="0 0 0" width="64" height="64"/>
    <material name="wheel_mat" texture="wheel_pat" texrepeat="8 1"
            specular=".5" shininess=".5"/>
    <mesh name="car_model" file="{STL_NAME}"
            scale=".05 .05 .05" maxhullvert="100"/>
  </asset>

  <!-- ========= 충돌 제외 ========= -->
  <contact>
    <exclude body1="front_left_susp"  body2="car"/>
    <exclude body1="front_right_susp" body2="car"/>
    <exclude body1="rear_left_susp"   body2="car"/>
    <exclude body1="rear_right_susp"  body2="car"/>
    <exclude body1="front_left_wheel"  body2="car"/>
    <exclude body1="front_right_wheel" body2="car"/>
    <exclude body1="rear_left_wheel"   body2="car"/>
    <exclude body1="rear_right_wheel"  body2="car"/>
  </contact>

  <!-- ========= 월드 ========= -->
  <worldbody>
    <!-- 조명 -->
    <light directional="true" diffuse=".8 .8 .8"
           specular=".2 .2 .2" pos="0 0 4" dir="0 0 -1"/>

    <!-- 바닥 : 충돌용 평면 -->
    <geom name="floor" type="plane" size="100 100 .1"
          material="grid_mat" contype="1" conaffinity="1" condim="3"
          friction="1 .02 .005"/>                        

    <!-- 차량 : 본체 + 바퀴 정의 -->
    <body name="car" pos="0 0 1.5">
      <joint name="root" type="free"/>
      <geom name="car_body" type="mesh" mesh="car_model" pos="0 0 0" euler="0 0 0"
            rgba=".5 .1 .1 .9" mass="{MASS_CHASSIS}" contype="1" conaffinity="1" margin="0.00001">
      </geom>

      <!-- 앞왼쪽 서스펜션 + 휠 -->
      <body name="front_left_susp" pos="1.25 1.5 0" euler="0 0 0">
        <inertial pos="0 0 0"
                  mass="{MASS_SUSP}"
                  diaginertia="{INERTIA_SUSP} {INERTIA_SUSP} {INERTIA_SUSP}"/>
        <joint name="fl_susp" type="slide" axis="0 0 1"
               range="-.15 .05" ref=".05"
               stiffness="{SPRING_K_F}" damping="{DAMP_SUSP}"/>
        <body name="front_left_wheel" pos="0 0 0">
          <joint name="fl_steer" type="hinge" axis="0 0 1" range="-.6 .6"/>
          <joint name="fl_wheel" type="hinge" axis="0 1 0"/>
          <geom name="fl_geom" type="cylinder" size="{WHEEL_DIAMETER} {WHEEL_WIDTH}"
                euler="90 0 0" material="wheel_mat" mass="{MASS_WHEEL}"
                solref="0.02 1" solimp="0.9 0.95 0.001" margin="0.01" friction="2 .02 .005"/>
          <site name="fl_site" pos="0 0 -{WHEEL_DIAMETER}" size=".01"/>
        </body>
      </body>
      
      <!-- 앞오른쪽 서스펜션 + 휠 -->
      <body name="front_right_susp" pos="1.25 -1.5 0" euler="0 0 0">
        <inertial pos="0 0 0"
                  mass="{MASS_SUSP}"
                  diaginertia="{INERTIA_SUSP} {INERTIA_SUSP} {INERTIA_SUSP}"/>
        <joint name="fr_susp" type="slide" axis="0 0 1"
               range="-.15 .05" ref=".05"
               stiffness="{SPRING_K_F}" damping="{DAMP_SUSP}"/>
        <body name="front_right_wheel" pos="0 0 0">
          <joint name="fr_steer" type="hinge" axis="0 0 1" range="-.6 .6"/>
          <joint name="fr_wheel" type="hinge" axis="0 1 0"/>
          <geom name="fr_geom" type="cylinder" size="{WHEEL_DIAMETER} {WHEEL_WIDTH}"
                euler="90 0 0" material="wheel_mat" mass="{MASS_WHEEL}"
                solref="0.02 1" solimp="0.9 0.95 0.001" margin="0.01" friction="2 .02 .005"/>
          <site name="fr_site" pos="0 0 -{WHEEL_DIAMETER}" size=".01"/>
        </body>
      </body>

      <!-- 뒤왼쪽 서스펜션 + 휠 -->
      <body name="rear_left_susp" pos="-1.5 1.5 0" euler="0 0 0">    <!-- 트럭 기울어짐이 있는것 같아 뒷바퀴 높이 조정-->
        <inertial pos="0 0 0"
                  mass="{MASS_SUSP}"
                  diaginertia="{INERTIA_SUSP} {INERTIA_SUSP} {INERTIA_SUSP}"/>
        <joint name="rl_susp" type="slide" axis="0 0 1"
               range="-.15 .05" ref=".05"
               stiffness="{SPRING_K_R}" damping="{DAMP_SUSP}"/>
        <body name="rear_left_wheel" pos="0 0 0">
          <joint name="rl_wheel" type="hinge" axis="0 1 0"/>
          <geom name="rl_geom" type="cylinder" size="{WHEEL_DIAMETER} {WHEEL_WIDTH}"
                euler="90 0 0" material="wheel_mat" mass="{MASS_WHEEL}"
                solref="0.02 1" solimp="0.9 0.95 0.001" margin="0.01" friction="2 .02 .005"/>
          <site name="rl_site" pos="0 0 -{WHEEL_DIAMETER}" size=".01"/>
        </body>
      </body>

      <!-- 뒤오른쪽 서스펜션 + 휠 -->
      <body name="rear_right_susp" pos="-1.5 -1.5 0" euler="0 0 0">   <!-- 트럭 기울어짐이 있는것 같아 뒷바퀴 높이 조정-->
        <inertial pos="0 0 0"
                  mass="{MASS_SUSP}"
                  diaginertia="{INERTIA_SUSP} {INERTIA_SUSP} {INERTIA_SUSP}"/>
        <joint name="rr_susp" type="slide" axis="0 1 0"
               range="-.15 .05" ref=".05"
               stiffness="{SPRING_K_R}" damping="{DAMP_SUSP}"/>
        <body name="rear_right_wheel" pos="0 0 0">
          <joint name="rr_wheel" type="hinge" axis="0 1 0"/>
          <geom name="rr_geom" type="cylinder" size="{WHEEL_DIAMETER} {WHEEL_WIDTH}"
                euler="90 0 0" material="wheel_mat" mass="{MASS_WHEEL}"
                solref="0.02 1" solimp="0.9 0.95 0.001" margin="0.01" friction="2 .02 .005"/>
          <site name="rr_site" pos="0 0 -{WHEEL_DIAMETER}" size=".01"/>
        </body>
      </body>
    </body>


    <!-- 기존 점프대 및 장애물 -->
    <geom name="jump_ramp_1" type="box" pos="-20 0 .1"
          size="1 1 .1" euler="0 15 0" rgba=".3 .8 .3 1"/>
    <geom name="jump_ramp_2" type="box" pos="20 0 .1"
          size="1 1 .1" euler="0 15 0" rgba=".3 .8 .3 1"/>

    <!-- 수화물 -->
    <body name="sphere_1" pos="0 0 6.5">
      <joint name="sphere_rot_1" type="free"/>
      <geom size="0.3 0.3 0.3" type="sphere" rgba="0.3 0.9 0.2 1" mass="10" 
            contype="1" conaffinity="1" friction="0.5 0.04 0.04"/> 
    </body>

  </worldbody>

  <!-- ========= 액추에이터 ========= -->
  <actuator>
    <motor name="fl_motor" joint="fl_wheel" ctrlrange="-100000 100000" gear="{GEAR_DRIVE}"/>
    <motor name="fr_motor" joint="fr_wheel" ctrlrange="-100000 100000" gear="{GEAR_DRIVE}"/>
    <motor name="rl_motor" joint="rl_wheel" ctrlrange="-100000 100000" gear="{GEAR_DRIVE}"/>
    <motor name="rr_motor" joint="rr_wheel" ctrlrange="-100000 100000" gear="{GEAR_DRIVE}"/>
    <motor name="fl_steer_motor" joint="fl_steer" ctrlrange="-4000 4000" gear="{GEAR_STEER}"/>
    <motor name="fr_steer_motor" joint="fr_steer" ctrlrange="-4000 4000" gear="{GEAR_STEER}"/>
    <motor name="fl_brake_motor" joint="fl_wheel" ctrlrange="-20000 20000" gear="{GEAR_BRAKE}"/>
    <motor name="fr_brake_motor" joint="fr_wheel" ctrlrange="-20000 20000" gear="{GEAR_BRAKE}"/>
    <motor name="rl_brake_motor" joint="rl_wheel" ctrlrange="-20000 20000" gear="{GEAR_BRAKE}"/>
    <motor name="rr_brake_motor" joint="rr_wheel" ctrlrange="-20000 20000" gear="{GEAR_BRAKE}"/>
  </actuator>

  <!-- ========= 센서 ========= -->
  <sensor>
    <force name="fl_force" site="fl_site"/>
    <force name="fr_force" site="fr_site"/>
    <force name="rl_force" site="rl_site"/>
    <force name="rr_force" site="rr_site"/>
  </sensor>
</mujoco>