<!--
목적 : (차량 모델 분리) 부분 트럭 모델
작성자 : 김준호
최초 작성일자 : 2025-05-09
수정자 : 김준호
최종 수정일자 : 2025-05-09
-->
<mujoco>
  <compiler inertiafromgeom="true"/>
  <option timestep="0.001" gravity="0 0 -9.81"/>

  <asset>
    <texture name="grid" type="2d" builtin="checker"
             rgb1="0.2 0.3 0.4" rgb2="0.8 0.8 0.8"
             width="512" height="512"/>
    <material name="grid_mat" texture="grid" texrepeat="5 5"
              specular="0.3" shininess="0.3"/>
    <texture name="wheel_pattern" type="2d" builtin="checker"
             rgb1="1 1 1" rgb2="0 0 0"
             width="64" height="64"/>
    <material name="wheel_mat" texture="wheel_pattern" texrepeat="8 1"
              specular="0.5" shininess="0.5"/>
    <mesh name="VAN_Front_mesh" file="VAN_Front.stl" scale="0.025 0.025 0.025" maxhullvert="100"/>
  </asset>

  <worldbody>
    <light directional="true" diffuse=".8 .8 .8" specular="0.2 0.2 0.2" pos="0 0 4" dir="0 0 -1"/>

    <!-- 바닥: 충돌용 평면 -->
    <geom name="floor" type="plane" size="50 50 0.1"
          material="grid_mat"
          friction="1 0.5 0.5"
          contype="1" conaffinity="1" condim="3"/>

    <!-- 차량 본체 + 바퀴 정의 -->
    <body name="chassis" pos="0 0 0.4">
      <joint name="root" type="free"/>
      <geom name="chassis" type="box" size="1.8 1.2 0.1" rgba="0.5 0.2 0.7 1" mass="50" friction="1 0.5 0.5"/>   1.875 1.25 0.375
      <geom name="wall_1" type="box" size="1.8 0.12 0.5" pos="0 1.08 0.5" rgba="0.5 0.2 0.7 0.5" mass="10" friction="1 0.5 0.5"/>
      <geom name="wall_2" type="box" size="1.8 0.12 .5" pos="0 -1.08 0.5" rgba="0.5 0.2 0.7 0.5" mass="10" friction="1 0.5 0.5"/>  
      <geom name="wall_3" type="box" size="0.18 1.2 .5" pos="-1.62 0 0.5" rgba="0.5 0.2 0.7 0.5" mass="1" friction="1 0.5 0.5"/>
      <geom name="VAN_Front" type="mesh" mesh="VAN_Front_mesh" pos="1.4 0 0" euler="0 0 -90" rgba="0.5 0.2 0.7 1" mass="10" friction="1 0.5 0.5"/>

      <!-- 앞왼쪽 바퀴 -->
      <body name="front_left_wheel" pos="1.25 1.4 0">
        <joint name="fl_steer" type="hinge" axis="0 0 1"
               range="-0.6 0.6" damping="0" stiffness="0"/>
        <joint name="fl_wheel" type="hinge" axis="0 1 0" damping="0"/>
        <geom name="fl_geom" type="cylinder" size="0.35 0.175"
              euler="90 0 0" material="wheel_mat"
              mass="5.0" friction="0 0 0"
              solimp="0.9 0.95 0.001 0.1 2"
              contype="1" conaffinity="1" condim="3"
              margin="0.001" gap="0.0001"/>
        <site name="fl_site" pos="0 0 -0.7" size="0.01" group="3"/>
      </body>

      <!-- 앞오른쪽 바퀴 -->
      <body name="front_right_wheel" pos="1.25 -1.4 0">
        <joint name="fr_steer" type="hinge" axis="0 0 1"
               range="-0.6 0.6" damping="0" stiffness="0"/>
        <joint name="fr_wheel" type="hinge" axis="0 1 0" damping="0"/>
        <geom name="fr_geom" type="cylinder" size="0.35 0.175"
              euler="90 0 0" material="wheel_mat"
              mass="5.0" friction="0 0 0"
              solimp="0.9 0.95 0.001 0.1 2"
              contype="1" conaffinity="1" condim="3"
              margin="0.001" gap="0.0001"/>
        <site name="fr_site" pos="0 0 -0.7" size="0.01" group="3"/>
      </body>

      <!-- 뒤왼쪽 바퀴 -->
      <body name="rear_left_wheel" pos="-1.25 1.4 0">
        <joint name="rl_wheel" type="hinge" axis="0 1 0" damping="0"/>
        <geom name="rl_geom" type="cylinder" size="0.35 0.175"
              euler="90 0 0" material="wheel_mat"
              mass="5.0" friction="0 0 0"
              solimp="0.9 0.95 0.001 0.1 2"
              contype="1" conaffinity="1" condim="3"
              margin="0.001" gap="0.0001"/>
        <site name="rl_site" pos="0 0 -0.7" size="0.01" group="3"/>
      </body>

      <!-- 뒤오른쪽 바퀴 -->
      <body name="rear_right_wheel" pos="-1.25 -1.4 0">
        <joint name="rr_wheel" type="hinge" axis="0 1 0" damping="0"/>
        <geom name="rr_geom" type="cylinder" size="0.35 0.175"
              euler="90 0 0" material="wheel_mat"
              mass="5.0" friction="0 0 0"
              solimp="0.9 0.95 0.001 0.1 2"
              contype="1" conaffinity="1" condim="3"
              margin="0.001" gap="0.0001"/>
        <site name="rr_site" pos="0 0 -0.7" size="0.01" group="3"/>
      </body>
    </body>

    <!-- 기존 점프대 및 장애물 -->
    <geom name="jump_ramp1" type="box" pos="-20 0 0.1"
          size="1 1 0.1" euler="0 15 0"
          rgba="0.8 0.5 0.3 1" friction="1 0.5 0.5"
          contype="1" conaffinity="1" condim="3"/>
    <geom name="jump_ramp2" type="box" pos="10 1 0.1"
          size="1 1 0.1" euler="0 15 0"
          rgba="0.8 0.5 0.3 1" friction="1 0.5 0.5"
          contype="1" conaffinity="1" condim="3"/>

    <geom name="obstacle1" type="box" pos="-50 -5 0.2"
          size="0.5 0.5 0.2" rgba="0.3 0.8 0.3 1" friction="1 0.5 0.5"
          contype="1" conaffinity="1" condim="3"/>
    <geom name="obstacle2" type="box" pos="-5 40 0.2"
          size="0.5 0.5 0.2" rgba="0.3 0.8 0.3 1" friction="1 0.5 0.5"
          contype="1" conaffinity="1" condim="3"/>
    <geom name="obstacle3" type="box" pos="0 10 0.2"
          size="0.5 0.5 0.2" rgba="0.3 0.8 0.3 1" friction="1 0.5 0.5"
          contype="1" conaffinity="1" condim="3"/>
    <geom name="obstacle4" type="box" pos="10 -5 0.2"
          size="0.5 0.5 0.2" rgba="0.3 0.8 0.3 1" friction="1 0.5 0.5"
          contype="1" conaffinity="1" condim="3"/>
    <geom name="obstacle5" type="box" pos="5 20 0.2"
          size="0.5 0.5 0.2" rgba="0.3 0.8 0.3 1" friction="1 0.5 0.5"
          contype="1" conaffinity="1" condim="3"/>
    <geom name="obstacle6" type="box" pos="-10 0 0.2"
          size="0.5 0.5 0.2" rgba="0.3 0.8 0.3 1" friction="1 0.5 0.5"
          contype="1" conaffinity="1" condim="3"/>

    <!-- 수화물 공 9개 -->
    <body name="sphere_1" pos="-0.4 -0.4 1">
      <joint name="sphere_rot_1" type="free"/>
      <geom size="0.1 0.1 0.1" type="sphere" rgba="0.1 0.9 0.2 1" mass="0.5" contype="1" conaffinity="1" friction="0.04 0.04 0.04"/> 
    </body>
    <body name="sphere_2" pos="-0.7 -0.4 1">
      <joint name="sphere_rot_2" type="free"/>
      <geom size="0.1 0.1 0.1" type="sphere" rgba="0.1 0.9 0.2 1" mass="0.5" contype="1" conaffinity="1" friction="0.04 0.04 0.04"/> 
    </body>
    <body name="sphere_3" pos="-1 -0.4 1">
      <joint name="sphere_rot_3" type="free"/>
      <geom size="0.1 0.1 0.1" type="sphere" rgba="0.1 0.9 0.2 1" mass="0.5" contype="1" conaffinity="1" friction="0.04 0.04 0.04"/> 
    </body>
    <body name="sphere_4" pos="-0.4 -0.7 1">
      <joint name="sphere_rot_4" type="free"/>
      <geom size="0.1 0.1 0.1" type="sphere" rgba="0.1 0.9 0.2 1" mass="0.5" contype="1" conaffinity="1" friction="0.04 0.04 0.04"/> 
    </body>
    <body name="sphere_5" pos="-0.7 -0.7 1">
      <joint name="sphere_rot_5" type="free"/>
      <geom size="0.1 0.1 0.1" type="sphere" rgba="0.1 0.9 0.2 1" mass="0.5" contype="1" conaffinity="1" friction="0.04 0.04 0.04"/> 
    </body>
    <body name="sphere_6" pos="-1 -0.7 1">
      <joint name="sphere_rot_6" type="free"/>
      <geom size="0.1 0.1 0.1" type="sphere" rgba="0.1 0.9 0.2 1" mass="0.5" contype="1" conaffinity="1" friction="0.04 0.04 0.04"/> 
    </body>
    <body name="sphere_7" pos="-0.4 -1 1">
      <joint name="sphere_rot_7" type="free"/>
      <geom size="0.1 0.1 0.1" type="sphere" rgba="0.1 0.9 0.2 1" mass="0.5" contype="1" conaffinity="1" friction="0.04 0.04 0.04"/> 
    </body>
    <body name="sphere_8" pos="-0.7 -1 1">
      <joint name="sphere_rot_8" type="free"/>
      <geom size="0.1 0.1 0.1" type="sphere" rgba="0.1 0.9 0.2 1" mass="0.5" contype="1" conaffinity="1" friction="0.04 0.04 0.04"/> 
    </body>
    <body name="sphere_9" pos="-1 -1 1">
      <joint name="sphere_rot_9" type="free"/>
      <geom size="0.1 0.1 0.1" type="sphere" rgba="0.1 0.9 0.2 1" mass="0.5" contype="1" conaffinity="1" friction="0.04 0.04 0.04"/> 
    </body>
  </worldbody>

  <!-- 액츄에이터 (바퀴 동력 및 조향) -->
  <actuator>
    <motor name="fl_motor" joint="fl_wheel"      ctrlrange="-2000 2000" gear="1"/>
    <motor name="fr_motor" joint="fr_wheel"      ctrlrange="-2000 2000" gear="1"/>
    <motor name="rl_motor" joint="rl_wheel"      ctrlrange="-2000 2000" gear="1"/>
    <motor name="rr_motor" joint="rr_wheel"      ctrlrange="-2000 2000" gear="1"/>
    <motor name="fl_steer_motor" joint="fl_steer" ctrlrange="-200 200"   gear="10"/>
    <motor name="fr_steer_motor" joint="fr_steer" ctrlrange="-200 200"   gear="10"/>
  </actuator>

  <!-- 힘 측정 센서-->
  <sensor>
    <force name="fl_force" site="fl_site"/>
    <force name="fr_force" site="fr_site"/>
    <force name="rl_force" site="rl_site"/>
    <force name="rr_force" site="rr_site"/>
  </sensor>
</mujoco>