<!--
목적 : (차량 모델 분리) SDF 트럭 모델
작성자 : 김준호
최초 작성일자 : 2025-05-09
수정자 : 김준호
최종 수정일자 : 2025-05-09
-->
<mujoco>
  <!-- SDF 플러그인으로 STL파일 mesh 충돌지정 -->
  <extension>
    <plugin plugin="mujoco.sdf.sdflib">
      <instance name="sdf">
        <config key="aabb" value="0" />
      </instance>
    </plugin>
  </extension>

  <compiler meshdir="." autolimits="true"/>

  <option timestep="0.001" gravity="0 0 -9.81"/>
  
  <asset>
    <texture name="grid" type="2d" builtin="checker" width="512" height="512" rgb1=".1 .2 .3" rgb2=".2 .3 .4"/>
    <material name="grid" texture="grid" texrepeat="1 1" texuniform="true" reflectance=".2"/>
    <mesh name="truckbody_original_mesh" file="truckbody_original.stl" scale="0.05 0.05 0.05" maxhullvert="100"/>
    <mesh name="tire_mesh" file="tire.stl" scale="0.05 0.05 0.05" maxhullvert="100"/> 
    <mesh name="wheel_mesh" file="wheel.stl" scale="0.05 0.05 0.05" maxhullvert="100"/>
    <texture name="wheel_pattern" type="2d" builtin="checker"
             rgb1="1 1 1" rgb2="0 0 0"
             width="64" height="64"/>
    <material name="wheel_mat" texture="wheel_pattern" texrepeat="8 1"
              specular="0.5" shininess="0.5"/>
    <material name="grid_mat" texture="grid" texrepeat="5 5"
              specular="0.3" shininess="0.3"/>
  </asset>

  <worldbody>
    <light directional="true" diffuse=".8 .8 .8" specular="0.2 0.2 0.2" pos="0 0 4" dir="0 0 -1"/>

    <!-- 바닥: 충돌용 평면 -->
    <geom name="floor" type="plane" size="50 50 0.1"
          material="grid_mat"
          friction="1 0.5 0.5"
          contype="1" conaffinity="1" condim="3"/>

    <!-- 차량 본체 + 바퀴 정의 -->
    <body name="truckbody_original" pos="0 3 1" euler="0 0 90">
      <joint name="root" type="free"/>
      <geom type="sdf" mesh="truckbody_original_mesh" rgba="0.8 0.1 0.2 1" mass="2" pos="0 0 0" euler="90 90 0" contype="1" conaffinity="1" margin="0.00001"> 
        <plugin instance="sdf" />      </geom>

      <!-- 앞왼쪽 바퀴 -->
      <body name="front_left_wheel" pos="0.3 0 0">
        <joint name="fl_steer" type="hinge" axis="0 0 1"
               range="-0.6 0.6" damping="0" stiffness="0"/>
        <joint name="fl_wheel" type="hinge" axis="1 0 0" damping="0"/>
        <geom name="fl_geom" type="cylinder" size="0.6 0.25"
              euler="0 90 0" material="wheel_mat"
              mass="7.0" friction="0 0 0"
              solimp="0.9 0.95 0.001 0.1 2"
              contype="1" conaffinity="1" condim="3"
              margin="0.001" gap="0.0001"/>
        <site name="fl_site" pos="0 0 -0.7" size="0.01" group="3"/>
      </body>

      <!-- 앞오른쪽 바퀴 -->
      <body name="front_right_wheel" pos="-2.8 0 0">
        <joint name="fr_steer" type="hinge" axis="0 0 1"
               range="-0.6 0.6" damping="0" stiffness="0"/>
        <joint name="fr_wheel" type="hinge" axis="1 0 0" damping="0"/>
        <geom name="fr_geom" type="cylinder" size="0.6 0.25"
              euler="0 90 0" material="wheel_mat"
              mass="7.0" friction="0 0 0"
              solimp="0.9 0.95 0.001 0.1 2"
              contype="1" conaffinity="1" condim="3"
              margin="0.001" gap="0.0001"/>
        <site name="fr_site" pos="0 0 -0.7" size="0.01" group="3"/>
      </body>

      <!-- 뒤왼쪽 바퀴 -->
      <body name="rear_left_wheel" pos="0.3 2.75 0">
        <joint name="rl_wheel" type="hinge" axis="1 0 0" damping="0"/>
        <geom name="rl_geom" type="cylinder" size="0.6 0.25"
              euler="0 90 0" material="wheel_mat"
              mass="1.0" friction="0 0 0"
              solimp="0.9 0.95 0.001 0.1 2"
              contype="1" conaffinity="1" condim="3"
              margin="0.001" gap="0.0001"/>
        <site name="rl_site" pos="0 0 -0.7" size="0.01" group="3"/>
      </body>

      <!-- 뒤오른쪽 바퀴 -->
      <body name="rear_right_wheel" pos="-2.8 2.75 0">
        <joint name="rr_wheel" type="hinge" axis="1 0 0" damping="0"/>
        <geom name="rr_geom" type="cylinder" size="0.6 0.25"
              euler="0 90 0" material="wheel_mat"
              mass="7.0" friction="0 0 0"
              solimp="0.9 0.95 0.001 0.1 2"
              contype="1" conaffinity="1" condim="3"
              margin="0.001" gap="0.0001"/>
        <site name="rr_site" pos="0 0 -0.7" size="0.01" group="3"/>
      </body>
    </body>

    <!-- 기존 점프대 및 장애물 -->
    <geom name="jump_ramp1" type="box" pos="-20 0 0.1"
          size="1 1 0.1" euler="0 15 0"
          rgba="0.8 0.5 0.3 1" friction="1 0.5 0.5"
          contype="1" conaffinity="1" condim="3"/>
    <geom name="jump_ramp2" type="box" pos="10 1 0.1"
          size="1 1 0.1" euler="0 15 0"
          rgba="0.8 0.5 0.3 1" friction="1 0.5 0.5"
          contype="1" conaffinity="1" condim="3"/>

    <geom name="obstacle1" type="box" pos="-50 -5 0.2"
          size="0.5 0.5 0.2" rgba="0.3 0.8 0.3 1" friction="1 0.5 0.5"
          contype="1" conaffinity="1" condim="3"/>
    <geom name="obstacle2" type="box" pos="-5 40 0.2"
          size="0.5 0.5 0.2" rgba="0.3 0.8 0.3 1" friction="1 0.5 0.5"
          contype="1" conaffinity="1" condim="3"/>
    <geom name="obstacle3" type="box" pos="0 10 0.2"
          size="0.5 0.5 0.2" rgba="0.3 0.8 0.3 1" friction="1 0.5 0.5"
          contype="1" conaffinity="1" condim="3"/>
    <geom name="obstacle4" type="box" pos="10 -5 0.2"
          size="0.5 0.5 0.2" rgba="0.3 0.8 0.3 1" friction="1 0.5 0.5"
          contype="1" conaffinity="1" condim="3"/>
    <geom name="obstacle5" type="box" pos="5 20 0.2"
          size="0.5 0.5 0.2" rgba="0.3 0.8 0.3 1" friction="1 0.5 0.5"
          contype="1" conaffinity="1" condim="3"/>
    <geom name="obstacle6" type="box" pos="-10 0 0.2"
          size="0.5 0.5 0.2" rgba="0.3 0.8 0.3 1" friction="1 0.5 0.5"
          contype="1" conaffinity="1" condim="3"/>

    <!-- 수화물 공 9개 -->
    <body name="sphere_1" pos="-1.8 2 4">
      <joint name="sphere_rot_1" type="free"/>
      <geom size="0.1 0.1 0.1" type="sphere" rgba="0.1 0.9 0.2 1" mass="0.5" contype="1" conaffinity="1" friction="0.04 0.04 0.04"/> 
    </body>
    <body name="sphere_2" pos="-2 2 4">
      <joint name="sphere_rot_2" type="free"/>
      <geom size="0.1 0.1 0.1" type="sphere" rgba="0.1 0.9 0.2 1" mass="0.5" contype="1" conaffinity="1" friction="0.04 0.04 0.04"/> 
    </body>
    <body name="sphere_3" pos="-2.2 2 4">
      <joint name="sphere_rot_3" type="free"/>
      <geom size="0.1 0.1 0.1" type="sphere" rgba="0.1 0.9 0.2 1" mass="0.5" contype="1" conaffinity="1" friction="0.04 0.04 0.04"/> 
    </body>
    <body name="sphere_4" pos="-1.8 2.2 4">
      <joint name="sphere_rot_4" type="free"/>
      <geom size="0.1 0.1 0.1" type="sphere" rgba="0.1 0.9 0.2 1" mass="0.5" contype="1" conaffinity="1" friction="0.04 0.04 0.04"/> 
    </body>
    <body name="sphere_5" pos="-2 2.2 4">
      <joint name="sphere_rot_5" type="free"/>
      <geom size="0.1 0.1 0.1" type="sphere" rgba="0.1 0.9 0.2 1" mass="0.5" contype="1" conaffinity="1" friction="0.04 0.04 0.04"/> 
    </body>
    <body name="sphere_6" pos="-2.2 2.2 4">
      <joint name="sphere_rot_6" type="free"/>
      <geom size="0.1 0.1 0.1" type="sphere" rgba="0.1 0.9 0.2 1" mass="0.5" contype="1" conaffinity="1" friction="0.04 0.04 0.04"/> 
    </body>
    <body name="sphere_7" pos="-1.8 2.4 4">
      <joint name="sphere_rot_7" type="free"/>
      <geom size="0.1 0.1 0.1" type="sphere" rgba="0.1 0.9 0.2 1" mass="0.5" contype="1" conaffinity="1" friction="0.04 0.04 0.04"/> 
    </body>
    <body name="sphere_8" pos="-2 2.4 4">
      <joint name="sphere_rot_8" type="free"/>
      <geom size="0.1 0.1 0.1" type="sphere" rgba="0.1 0.9 0.2 1" mass="0.5" contype="1" conaffinity="1" friction="0.04 0.04 0.04"/> 
    </body>
    <body name="sphere_9" pos="-2.2 2.4 4">
      <joint name="sphere_rot_9" type="free"/>
      <geom size="0.1 0.1 0.1" type="sphere" rgba="0.1 0.9 0.2 1" mass="0.5" contype="1" conaffinity="1" friction="0.04 0.04 0.04"/> 
    </body>
  </worldbody>

  <!-- 액츄에이터 (바퀴 동력 및 조향) -->
  <actuator>
    <motor name="fl_motor" joint="fl_wheel" ctrlrange="-2000 2000" gear="1"/>
    <motor name="fr_motor" joint="fr_wheel" ctrlrange="-2000 2000" gear="1"/>
    <motor name="rl_motor" joint="rl_wheel" ctrlrange="-2000 2000" gear="1"/>
    <motor name="rr_motor" joint="rr_wheel" ctrlrange="-2000 2000" gear="1"/>
    <motor name="fl_steer" joint="fl_steer" ctrlrange="-100 100" gear="10"/>
    <motor name="fr_steer" joint="fr_steer" ctrlrange="-100 100" gear="10"/>
  </actuator>

  <!-- 힘 측정 센서-->
  <sensor>
    <force name="fl_force" site="fl_site"/>
    <force name="fr_force" site="fr_site"/>
    <force name="rl_force" site="rl_site"/>
    <force name="rr_force" site="rr_site"/>
  </sensor>
</mujoco>